172.20.30.156
[I 15:11:38.022 NotebookApp] Writing notebook server cookie secret to /root/.local/share/jupyter/runtime/notebook_cookie_secret
[I 15:11:38.321 NotebookApp] Serving notebooks from local directory: /tf
[I 15:11:38.323 NotebookApp] Jupyter Notebook 6.4.5 is running at:
[I 15:11:38.326 NotebookApp] http://c35b711f1ed4:8888/?token=8375eb873e65484763ef12f81d82f1e018ca701ef7c5ddda
[I 15:11:38.328 NotebookApp]  or http://127.0.0.1:8888/?token=8375eb873e65484763ef12f81d82f1e018ca701ef7c5ddda
[I 15:11:38.330 NotebookApp] Use Control-C to stop this server and shut down all kernels (twice to skip confirmation).
[C 15:11:38.338 NotebookApp] 
    
    To access the notebook, open this file in a browser:
        file:///root/.local/share/jupyter/runtime/nbserver-19-open.html
    Or copy and paste one of these URLs:
        http://c35b711f1ed4:8888/?token=8375eb873e65484763ef12f81d82f1e018ca701ef7c5ddda
     or http://127.0.0.1:8888/?token=8375eb873e65484763ef12f81d82f1e018ca701ef7c5ddda
[I 15:12:00.494 NotebookApp] interrupted
jupyter_http_over_ws extension initialized. Listening on /http_over_websocket
Serving notebooks from local directory: /tf
0 active kernels
Jupyter Notebook 6.4.5 is running at:
http://c35b711f1ed4:8888/?token=8375eb873e65484763ef12f81d82f1e018ca701ef7c5ddda
 or http://127.0.0.1:8888/?token=8375eb873e65484763ef12f81d82f1e018ca701ef7c5ddda
Shutdown this notebook server (y/[n])? [C 15:12:00.774 NotebookApp] received signal 2, stopping
[I 15:12:00.777 NotebookApp] Shutting down 0 kernels
[I 15:12:00.787 NotebookApp] Shutting down 0 terminals
[I 15:17:10.877 NotebookApp] Serving notebooks from local directory: /tf
[I 15:17:10.881 NotebookApp] Jupyter Notebook 6.4.5 is running at:
[I 15:17:10.884 NotebookApp] http://16719f910f3a:8888/?token=63e5c6945004dec255017b769771aa90fbc41925b6aff683
[I 15:17:10.887 NotebookApp]  or http://127.0.0.1:8888/?token=63e5c6945004dec255017b769771aa90fbc41925b6aff683
[I 15:17:10.889 NotebookApp] Use Control-C to stop this server and shut down all kernels (twice to skip confirmation).
[C 15:17:10.899 NotebookApp] 
    
    To access the notebook, open this file in a browser:
        file:///root/.local/share/jupyter/runtime/nbserver-32-open.html
    Or copy and paste one of these URLs:
        http://16719f910f3a:8888/?token=63e5c6945004dec255017b769771aa90fbc41925b6aff683
     or http://127.0.0.1:8888/?token=63e5c6945004dec255017b769771aa90fbc41925b6aff683
[I 15:18:46.609 NotebookApp] 302 GET /?token=63e5c6945004dec255017b769771aa90fbc41925b6aff683 (172.20.31.49) 1.060000ms
[I 15:18:53.588 NotebookApp] Writing notebook-signing key to /root/.local/share/jupyter/notebook_secret
[W 15:18:53.609 NotebookApp] Notebook proj_depo/dcgan/model_0/dcgan.ipynb is not trusted
[W 15:18:53.957 NotebookApp] 404 GET /notebooks/proj_depo/dcgan/model_0/images/gan1.png (172.20.31.49): No such file or directory: proj_depo/dcgan/model_0/images/gan1.png
[W 15:18:53.972 NotebookApp] 404 GET /notebooks/proj_depo/dcgan/model_0/images/gan1.png (172.20.31.49) 19.030000ms referer=http://194.95.108.157:8888/notebooks/proj_depo/dcgan/model_0/dcgan.ipynb
[W 15:18:53.975 NotebookApp] 404 GET /notebooks/proj_depo/dcgan/model_0/images/gan2.png (172.20.31.49): No such file or directory: proj_depo/dcgan/model_0/images/gan2.png
[W 15:18:53.979 NotebookApp] 404 GET /notebooks/proj_depo/dcgan/model_0/images/gan2.png (172.20.31.49) 4.630000ms referer=http://194.95.108.157:8888/notebooks/proj_depo/dcgan/model_0/dcgan.ipynb
ERROR:asyncio:Exception in callback <TaskWakeupMethWrapper object at 0x7f4263090b80>(<Future finis...C: 1\r\n\r\n'>)
handle: <Handle <TaskWakeupMethWrapper object at 0x7f4263090b80>(<Future finis...C: 1\r\n\r\n'>)>
Traceback (most recent call last):
  File "/usr/lib/python3.8/asyncio/events.py", line 81, in _run
    self._context.run(self._callback, *self._args)
RuntimeError: Cannot enter into task <Task pending name='Task-45' coro=<HTTP1ServerConnection._server_request_loop() running at /usr/local/lib/python3.8/dist-packages/tornado/http1connection.py:823> wait_for=<Future finished result=b'GET /kernel...PC: 1\r\n\r\n'> cb=[IOLoop.add_future.<locals>.<lambda>() at /usr/local/lib/python3.8/dist-packages/tornado/ioloop.py:688]> while another task <Task pending name='Task-1' coro=<MultiKernelManager._async_start_kernel() running at /usr/local/lib/python3.8/dist-packages/jupyter_client/multikernelmanager.py:186>> is being executed.
ERROR:asyncio:Exception in callback <TaskWakeupMethWrapper object at 0x7f4262ef7af0>(<Future finis...C: 1\r\n\r\n'>)
handle: <Handle <TaskWakeupMethWrapper object at 0x7f4262ef7af0>(<Future finis...C: 1\r\n\r\n'>)>
Traceback (most recent call last):
  File "/usr/lib/python3.8/asyncio/events.py", line 81, in _run
    self._context.run(self._callback, *self._args)
RuntimeError: Cannot enter into task <Task pending name='Task-28' coro=<HTTP1ServerConnection._server_request_loop() running at /usr/local/lib/python3.8/dist-packages/tornado/http1connection.py:823> wait_for=<Future finished result=b'GET /api/co...PC: 1\r\n\r\n'> cb=[IOLoop.add_future.<locals>.<lambda>() at /usr/local/lib/python3.8/dist-packages/tornado/ioloop.py:688]> while another task <Task pending name='Task-1' coro=<MultiKernelManager._async_start_kernel() running at /usr/local/lib/python3.8/dist-packages/jupyter_client/multikernelmanager.py:186>> is being executed.
[I 15:18:54.872 NotebookApp] Kernel started: 58598e8d-188a-4305-aa96-cbb26b37d6a0, name: python3
[I 15:18:55.699 NotebookApp] Adapting from protocol version 5.1 (kernel 58598e8d-188a-4305-aa96-cbb26b37d6a0) to 5.3 (client).
2021-11-29 15:20:04.643539: I tensorflow/core/platform/cpu_feature_guard.cc:151] This TensorFlow binary is optimized with oneAPI Deep Neural Network Library (oneDNN) to use the following CPU instructions in performance-critical operations:  AVX2 AVX512F FMA
To enable them in other operations, rebuild TensorFlow with the appropriate compiler flags.
2021-11-29 15:20:08.517514: I tensorflow/core/common_runtime/gpu/gpu_device.cc:1525] Created device /job:localhost/replica:0/task:0/device:GPU:0 with 10406 MB memory:  -> device: 0, name: GeForce GTX 1080 Ti, pci bus id: 0000:1a:00.0, compute capability: 6.1
2021-11-29 15:20:08.541982: I tensorflow/core/common_runtime/gpu/gpu_device.cc:1525] Created device /job:localhost/replica:0/task:0/device:GPU:1 with 10406 MB memory:  -> device: 1, name: GeForce GTX 1080 Ti, pci bus id: 0000:1b:00.0, compute capability: 6.1
2021-11-29 15:20:08.546598: I tensorflow/core/common_runtime/gpu/gpu_device.cc:1525] Created device /job:localhost/replica:0/task:0/device:GPU:2 with 10406 MB memory:  -> device: 2, name: GeForce GTX 1080 Ti, pci bus id: 0000:1c:00.0, compute capability: 6.1
2021-11-29 15:20:08.551967: I tensorflow/core/common_runtime/gpu/gpu_device.cc:1525] Created device /job:localhost/replica:0/task:0/device:GPU:3 with 10406 MB memory:  -> device: 3, name: GeForce GTX 1080 Ti, pci bus id: 0000:1d:00.0, compute capability: 6.1
2021-11-29 15:20:08.556442: I tensorflow/core/common_runtime/gpu/gpu_device.cc:1525] Created device /job:localhost/replica:0/task:0/device:GPU:4 with 10406 MB memory:  -> device: 4, name: GeForce GTX 1080 Ti, pci bus id: 0000:1e:00.0, compute capability: 6.1
2021-11-29 15:20:11.592095: I tensorflow/stream_executor/cuda/cuda_dnn.cc:366] Loaded cuDNN version 8100
[I 15:20:56.441 NotebookApp] Saving file at /proj_depo/dcgan/model_0/dcgan.ipynb
[W 15:20:56.444 NotebookApp] Notebook proj_depo/dcgan/model_0/dcgan.ipynb is not trusted
2021-11-29 15:21:11.259863: W tensorflow/core/framework/op_kernel.cc:1745] OP_REQUIRES failed at save_restore_v2_ops.cc:158 : NOT_FOUND: /tf/proj_depo/dcgan/model/training_checkpoints/ckpt-1_temp/part-00000-of-00001.data-00000-of-00001.tempstate594206592721218627; No such file or directory
[I 15:22:56.444 NotebookApp] Saving file at /proj_depo/dcgan/model_0/dcgan.ipynb
[W 15:22:56.448 NotebookApp] Notebook proj_depo/dcgan/model_0/dcgan.ipynb is not trusted
[I 15:23:23.220 NotebookApp] Starting buffering for 58598e8d-188a-4305-aa96-cbb26b37d6a0:4eb2530b260447938e9061c1f276bd33
[I 15:42:25.385 NotebookApp] Writing notebook server cookie secret to /root/.local/share/jupyter/runtime/notebook_cookie_secret
[I 15:42:25.687 NotebookApp] Serving notebooks from local directory: /tf
[I 15:42:25.689 NotebookApp] Jupyter Notebook 6.4.5 is running at:
[I 15:42:25.692 NotebookApp] http://daad585982f8:8888/?token=74d3576e9385ef2957465efc9b26f7ecba898002d098d4ca
[I 15:42:25.694 NotebookApp]  or http://127.0.0.1:8888/?token=74d3576e9385ef2957465efc9b26f7ecba898002d098d4ca
[I 15:42:25.696 NotebookApp] Use Control-C to stop this server and shut down all kernels (twice to skip confirmation).
[C 15:42:25.702 NotebookApp] 
    
    To access the notebook, open this file in a browser:
        file:///root/.local/share/jupyter/runtime/nbserver-27-open.html
    Or copy and paste one of these URLs:
        http://daad585982f8:8888/?token=74d3576e9385ef2957465efc9b26f7ecba898002d098d4ca
     or http://127.0.0.1:8888/?token=74d3576e9385ef2957465efc9b26f7ecba898002d098d4ca
[I 15:43:14.128 NotebookApp] The port 8888 is already in use, trying another port.
[I 15:43:14.131 NotebookApp] Serving notebooks from local directory: /tf
[I 15:43:14.133 NotebookApp] Jupyter Notebook 6.4.5 is running at:
[I 15:43:14.135 NotebookApp] http://daad585982f8:8889/?token=a83f22a3fe6ccbfc8459d98f3c2b4d48ddcd55be420ec12c
[I 15:43:14.137 NotebookApp]  or http://127.0.0.1:8889/?token=a83f22a3fe6ccbfc8459d98f3c2b4d48ddcd55be420ec12c
[I 15:43:14.139 NotebookApp] Use Control-C to stop this server and shut down all kernels (twice to skip confirmation).
[C 15:43:14.144 NotebookApp] 
    
    To access the notebook, open this file in a browser:
        file:///root/.local/share/jupyter/runtime/nbserver-31-open.html
    Or copy and paste one of these URLs:
        http://daad585982f8:8889/?token=a83f22a3fe6ccbfc8459d98f3c2b4d48ddcd55be420ec12c
     or http://127.0.0.1:8889/?token=a83f22a3fe6ccbfc8459d98f3c2b4d48ddcd55be420ec12c
[I 15:44:06.417 NotebookApp] 302 GET /?token=74d3576e9385ef2957465efc9b26f7ecba898002d098d4ca (172.20.31.49) 1.220000ms
[I 15:44:15.429 NotebookApp] Writing notebook-signing key to /root/.local/share/jupyter/notebook_secret
[W 15:44:15.443 NotebookApp] Notebook proj_depo/dcgan/model_0/dcgan.ipynb is not trusted
[W 15:44:15.822 NotebookApp] 404 GET /notebooks/proj_depo/dcgan/model_0/images/gan1.png (172.20.31.49): No such file or directory: proj_depo/dcgan/model_0/images/gan1.png
[W 15:44:15.839 NotebookApp] 404 GET /notebooks/proj_depo/dcgan/model_0/images/gan1.png (172.20.31.49) 20.960000ms referer=http://194.95.108.157:8888/notebooks/proj_depo/dcgan/model_0/dcgan.ipynb
[W 15:44:15.844 NotebookApp] 404 GET /notebooks/proj_depo/dcgan/model_0/images/gan2.png (172.20.31.49): No such file or directory: proj_depo/dcgan/model_0/images/gan2.png
[W 15:44:15.849 NotebookApp] 404 GET /notebooks/proj_depo/dcgan/model_0/images/gan2.png (172.20.31.49) 30.710000ms referer=http://194.95.108.157:8888/notebooks/proj_depo/dcgan/model_0/dcgan.ipynb
ERROR:asyncio:Exception in callback <TaskWakeupMethWrapper object at 0x7fee08377e80>(<Future finis...C: 1\r\n\r\n'>)
handle: <Handle <TaskWakeupMethWrapper object at 0x7fee08377e80>(<Future finis...C: 1\r\n\r\n'>)>
Traceback (most recent call last):
  File "/usr/lib/python3.8/asyncio/events.py", line 81, in _run
    self._context.run(self._callback, *self._args)
RuntimeError: Cannot enter into task <Task pending name='Task-9' coro=<HTTP1ServerConnection._server_request_loop() running at /usr/local/lib/python3.8/dist-packages/tornado/http1connection.py:823> wait_for=<Future finished result=b'GET /kernel...PC: 1\r\n\r\n'> cb=[IOLoop.add_future.<locals>.<lambda>() at /usr/local/lib/python3.8/dist-packages/tornado/ioloop.py:688]> while another task <Task pending name='Task-1' coro=<MultiKernelManager._async_start_kernel() running at /usr/local/lib/python3.8/dist-packages/jupyter_client/multikernelmanager.py:186>> is being executed.
ERROR:asyncio:Exception in callback <TaskWakeupMethWrapper object at 0x7fee083ca580>(<Future finis...C: 1\r\n\r\n'>)
handle: <Handle <TaskWakeupMethWrapper object at 0x7fee083ca580>(<Future finis...C: 1\r\n\r\n'>)>
Traceback (most recent call last):
  File "/usr/lib/python3.8/asyncio/events.py", line 81, in _run
    self._context.run(self._callback, *self._args)
RuntimeError: Cannot enter into task <Task pending name='Task-15' coro=<HTTP1ServerConnection._server_request_loop() running at /usr/local/lib/python3.8/dist-packages/tornado/http1connection.py:823> wait_for=<Future finished result=b'GET /api/co...PC: 1\r\n\r\n'> cb=[IOLoop.add_future.<locals>.<lambda>() at /usr/local/lib/python3.8/dist-packages/tornado/ioloop.py:688]> while another task <Task pending name='Task-1' coro=<MultiKernelManager._async_start_kernel() running at /usr/local/lib/python3.8/dist-packages/jupyter_client/multikernelmanager.py:186>> is being executed.
[I 15:44:16.754 NotebookApp] Kernel started: 1829ac69-82d7-46fa-a04f-e3668d9e9b39, name: python3
[I 15:44:17.226 NotebookApp] Adapting from protocol version 5.1 (kernel 1829ac69-82d7-46fa-a04f-e3668d9e9b39) to 5.3 (client).
[I 15:44:40.504 NotebookApp] Saving file at /proj_depo/dcgan/model_0/dcgan.ipynb
[W 15:44:40.507 NotebookApp] Notebook proj_depo/dcgan/model_0/dcgan.ipynb is not trusted
[I 15:45:00.939 NotebookApp] Saving file at /proj_depo/dcgan/model_0/dcgan.ipynb
[W 15:45:00.942 NotebookApp] Notebook proj_depo/dcgan/model_0/dcgan.ipynb is not trusted
[I 15:48:19.890 NotebookApp] Starting buffering for 1829ac69-82d7-46fa-a04f-e3668d9e9b39:2c1ea79785ef4a8cb700c5ab37d1e8a4
[I 17:11:24.240 NotebookApp] 302 GET /?token=402a3001b1da0aa7ff4422347f221d19e6e392ec557245e6 (172.20.31.49) 1.030000ms
